Workbook

Sheet Legend, definitions & instr
B1: Main Objective
B3: Calculate the demand for Service Center and HMH's capacity, ensuring the predictability needed to meet projects and to enable decisions to be made in advance.
B5: Type | C5: Definition
B7: Firm | C7: Projects with PO, or in other words, backlog
B8: Risk Release | C8: Forecasted projects, but evaluated in LOB to be as firm that it is initiated even with a PO
B9: Forecast | C9: Forecasted projects, in budget, however still not certain.
B10: Avg hours per Phase | C10: Average time consumption in hours expected per phase (considering transactional projects)
B11: Avr Lead time per Phase | C11: Average time consumption in mothns expected per phase (considering transactional projects)
B13: Legends | C13: FCTS | D13: Forecast
C14: FIRM | D14: Backlog (with PO)
B16: The Ideal Design
B45: RCCP Service Center - Premises / Rules
B47: Demand Control | C47: In this table, need to fill all projects and your informations.
C48: In this table, have all months of the year, need to be distributed the total hours per total lead time, the formula is: (Avg Hours per Phase (Hours) * Quantity) / Avg Lead time Phase (Months).
C49: We need to pay attention to filling the demand from the "start month".
C50: In the demand table of the tab "RCCP SAM" is automatic, not need to fill.
B51: Capacity Control | C51: Need to calculate the capacity in relation of the workdays.
C52: Overtime only occurs when demand is greater than capacity.
C53: HMH capacity is calculated on one line, contractors on another and we have unavailable, which is a vacation reference value.
B54: RCCP - Graphic | C54: When filling in the data, you need to insert a text box with white letters in the RCCP graphic and enter the product line of the area.
C55: The Graphic is automatized, we need only to fill the demand and capacity.
C56: The Graphic have your values in thousand hours.
B60: Projects Control
B61: The table below it's necessary to fill all projects and your informations.
B80: Distribution of Demand in hours
B81: Calculations sources: | C81: Definitions
B82: Firm, Risk Release or Forecast | C82: The distribution of hours is as below:
C84: (Avg Hours per Phase (Hours) * Quantity) / Avg Lead time Phase (Months)
C86: Ex: H-4 Connector
C87: Avg Hours per Phase (Hours) | D87: 968
C88: Quantity | D88: 2
C89: Avg Lead time Phase (Months) | D89: 4
C90: Start Month | D90: January
C91: 2025
C92: Jan | D92: Fev | E92: March | F92: Apr
C93: =(D87*D88)/D89 -> 484 | D93: =(D87*D88)/D89 -> 484 | E93: =(D87*D88)/D89 -> 484 | F93: =(D87*D88)/D89 -> 484
C94: Note: Important to understand that this result need to be spread according to the lead time
B107: Capacity Calculation in Hours
B108: Calculations resources: | C108: Definitions
B109: HMH employee and contractors | C109: For calculation HMH employees we use the formula below:
...

Sheet Projects Overview
A1: Product Line | B1: Equipment | C1: Project Name | D1: Quantity | E1: Project Phase | F1: Project Scope | G1: Type | H1: Project Status | I1: Start Month | J1: Start Year | K1: Avg hours per Phase (Hours) | L1: Avg Lead time phase (Months) | M1: January-25 | N1: February-25 | O1: March-25 | P1: April-25 | Q1: May-25 | R1: June-25 | S1: July-25 | T1: August-25 | U1: September-25 | V1: October-25 | W1: November-25 | X1: December-25 | Y1: January-26 | Z1: February-26 | AA1: March-26 | AB1: April-26 | AC1: May-26 | AD1: June-26 | AE1: July-26 | AF1: August-26 | AG1: September-26 | AH1: October-26 | AI1: November-26 | AJ1: December-26 | AK1: January-27 | AL1: February-27 | AM1: March-27 | AN1: April-27 | AO1: May-27 | AP1: June-27 | AQ1: July-27 | AR1: August-27 | AS1: September-27 | AT1: October-27 | AU1: November-27 | AV1: December-27
A2: Pressure Control | B2: H4 Connector | C2: TOI - H4 Connector - Transocean (From by sales) - SHD | D2: 1 | E2: FPA | F2: FPA | G2: Firm | H2: Concluded | I2: March-25 | J2: 2025 | K2: =968+242 -> 1210 | L2: 10 | O2: 172.85714 | P2: 172.85714 | Q2: 172.85714 | R2: 172.85714 | S2: 102 | T2: 50 | U2: 100 | X2: 137 | Y2: 130 | Z2: 130
A3: Pressure Control | B3: H4 Connector | C3: TOI - H4 Connector - Transocean (From by sales) - DWHD - Petrobras 1000 | D3: 1 | E3: FPA | F3: FPA | G3: Forecast | H3: Waiting PO | I3: March-26 | J3: 2026 | K3: 1168 | L3: 3 | AA3: =($K3*$D3)/$L3 -> 389.33333 | AB3: =($K3*$D3)/$L3 -> 389.33333 | AC3: =($K3*$D3)/$L3 -> 389.33333
A4: Pressure Control | B4: H4 Connector | C4: TOI - H4 Connector - Transocean (From by sales) - ExF - Petrobras 1000 | D4: 1 | E4: FPA | F4: FPA | G4: Firm | H4: WIP | I4: November-25 | J4: 2025 | K4: 650 | L4: 3 | W4: 350 | X4: 150 | Y4: 150 | Z4: 90 | AA4: 40
A5: Pressure Control | B5: H4 Connector | C5: TOI - H4 Connector - Transocean (From by sales) CX modificantion - DxE - SO 470005658 | D5: 1 | E5: FPA | F5: FPA | G5: Firm | H5: Concluded | I5: August-25 | J5: 2025 | K5: 533 | L5: 4 | T5: 133.33333 | U5: 133.33333 | V5: 133.33333 | W5: 133.33333
A6: Pressure Control | B6: H4 Connector | C6: CON-H4 Connector ExF Amaralina Star - Constellation (From by Project) - 470005343 | D6: 1 | E6: FPA | F6: FPA | G6: Firm | H6: Concluded | I6: May-25 | J6: 2025 | K6: 1330 | L6: 6 | Q6: 242 | R6: 350 | S6: 50 | T6: 150 | U6: 160 | V6: 300 | W6: 78
A7: Pressure Control | B7: Bonnet | C7: VEN - Bonnet - Ventura (From by projects) | D7: 1 | E7: FPA | F7: FPA | G7: Firm | H7: Concluded | I7: February-25 | J7: 2025 | K7: 816 | L7: 3 | N7: =($K7*$D7)/$L7 -> 272 | O7: =($K7*$D7)/$L7 -> 272 | P7: =($K7*$D7)/$L7 -> 272
A8: Pressure Control | B8: Bonnet | C8: VEN - Bonnet - Ventura (From by projects) | D8: 1 | E8: FPA | F8: FPA | G8: Firm | H8: Concluded | I8: February-25 | J8: 2025 | K8: 816 | L8: 3 | N8: =($K8*$D8)/$L8 -> 272 | O8: =($K8*$D8)/$L8 -> 272 | P8: =($K8*$D8)/$L8 -> 272
A9: Pressure Control | B9: Bonnet | C9: VEN - Bonnet - Ventura (From by projects) | D9: 1 | E9: D&I | F9: Transactional | G9: Firm | H9: Concluded | I9: February-25 | J9: 2025 | K9: 100 | L9: 1 | N9: =($K9*$D9)/$L9 -> 100
A10: Pressure Control | B10: Bonnet | C10: VEN - Bonnet - Ventura (From by projects) | D10: 1 | E10: D&I | F10: Transactional | G10: Firm | H10: Concluded | I10: February-25 | J10: 2025 | K10: 100 | L10: 1 | N10: =($K10*$D10)/$L10 -> 100
A11: Pressure Control | B11: Bonnet | C11: VEN - Bonnet - Ventura (From by projects) - 470005332 | D11: 1 | E11: Repair | F11: Transactional | G11: Firm | H11: WIP | I11: June-25 | J11: 2025 | K11: 820 | L11: 5 | R11: 172 | S11: 100 | T11: 100 | U11: 144 | V11: 184 | W11: 150 | X11: 150 | Y11: 70 | Z11: 30 | AA11: 70
A12: Pressure Control | B12: Bonnet | C12: VEN - Bonnet - Ventura (From by projects) - 470005333 | D12: 1 | E12: Repair | F12: Transactional | G12: Firm | H12: WIP | I12: June-25 | J12: 2025 | K12: 700 | L12: 5 | R12: 172 | S12: 100 | T12: 100 | U12: 144 | V12: 184 | W12: 150 | X12: 150 | Y12: 50
A13: Pressure Control | B13: Bonnet | C13: CON-Bonnet 4604405 - Constellation (From by projects) | D13: 1 | E13: T&A | F13: Transactional | G13: Forecast | H13: Waiting PO | I13: April-26 | J13: 2026 | K13: 132 | L13: 1 | AB13: =($K13*$D13)/$L13 -> 132
A14: Pressure Control | B14: Bonnet | C14: CON-Bonnet 4604427 - Constellation (From by projects) | D14: 1 | E14: T&A | F14: Transactional | G14: Forecast | H14: Waiting PO | I14: April-26 | J14: 2026 | K14: 132 | L14: 1 | AB14: =($K14*$D14)/$L14 -> 132
A15: Pressure Control | B15: H4 Connector | C15: CON - Conector H4 - 4604268 - Constellation | D15: 1 | E15: T&A | F15: Transactional | G15: Forecast | H15: Waiting Parts | I15: March-26 | J15: 2026 | K15: 176 | L15: 1 | AA15: =($K15*$D15)/$L15 -> 176
A16: Pressure Control | B16: H4 Connector | C16: CON - Conector H4 - 470000706 - Constellation | D16: 1 | E16: T&A | F16: Transactional | G16: Firm | H16: Concluded | I16: February-26 | J16: 2025 | K16: 176 | L16: 2 | X16: =($K16*$D16)/$L16 -> 88 | Y16: =($K16*$D16)/$L16 -> 88
A17: Pressure Control | B17: Bonnet | C17: CON-Bonnet 4604404 - Constellation (From by projects) | D17: 1 | E17: T&A | F17: Transactional | G17: Forecast | H17: Waiting PO | I17: April-26 | J17: 2026 | K17: 132 | L17: 1 | AB17: =($K17*$D17)/$L17 -> 132
A18: Pressure Control | B18: Bonnet | C18: CON-Bonnet 4604380 - Constellation (From by projects) | D18: 1 | E18: T&A | F18: Transactional | G18: Forecast | H18: Waiting PO | I18: April-26 | J18: 2026 | K18: 132 | L18: 1 | AB18: =($K18*$D18)/$L18 -> 132
A19: Pressure Control | B19: Bonnet | C19: CON-Bonnet 470001804 - Constellation (From by projects) | D19: 1 | E19: T&A | F19: Transactional | G19: Forecast | H19: Waiting PO | I19: May-26 | J19: 2026 | K19: 132 | L19: 1 | AC19: =($K19*$D19)/$L19 -> 132
A20: Pressure Control | B20: Bonnet | C20: FOR-Bonnet 15-3K 470002470- Foresea (From by projects) | D20: 1 | E20: Repair | F20: Transactional | G20: Firm | H20: Concluded | I20: February-26 | J20: 2025 | K20: 1068 | L20: 8 | O20: 117 | P20: 117 | Q20: 117 | R20: 100 | S20: 100 | T20: 100 | U20: 117 | V20: 150 | W20: 150
A21: Pressure Control | B21: Bonnet | C21: FOR-Bonnet 15-3K 470002553- Foresea (From by projects) | D21: 1 | E21: Repair | F21: Transactional | G21: Firm | H21: Concluded | I21: February-26 | J21: 2025 | K21: 1068 | L21: 8 | O21: 117 | P21: 117 | Q21: 117 | R21: 100 | S21: 100 | T21: 100 | U21: 117 | V21: 150 | W21: 150
A22: Pressure Control | B22: Annular Piston | C22: VLS - Annular Piston - Valaris (From by projects) | D22: 1 | E22: Repair | F22: Transactional | G22: Firm | H22: Concluded | I22: February-26 | J22: 2025 | K22: 396 | L22: 4 | M22: =($K22*$D22)/$L22 -> 99 | N22: =($K22*$D22)/$L22 -> 99 | O22: =($K22*$D22)/$L22 -> 99 | P22: =($K22*$D22)/$L22 -> 99
A23: Pressure Control | B23: Female Stab | C23: CON-Female Stab - Manufacturing Process | D23: 1 | E23: Manufacturing | F23: Transactional | G23: Firm | H23: WIP | I23: February-26 | J23: 2026 | K23: 125 | L23: 1 | AA23: =($K23*$D23)/$L23 -> 125
A24: Pressure Control | B24: Female Stab | C24: CON-Female Stab - Complete (From by Projects) | D24: 1 | E24: D&I | F24: Transactional | G24: Firm | H24: Concluded | I24: February-26 | J24: 2025 | K24: 564.5 | L24: 1 | R24: =($K24*$D24)/$L24 -> 564.5
A25: Pressure Control | B25: Female Stab | C25: CON-Female Stab - Piston (From by Projects) | D25: 1 | E25: D&I | F25: Transactional | G25: Firm | H25: Concluded | I25: February-26 | J25: 2025 | K25: 124.5 | L25: 1 | P25: =($K25*$D25)/$L25 -> 124.5
A26: Pressure Control | B26: Ram Block | C26: CON - Ram Block - Constellation - 470004598 (From by sales) | D26: 1 | E26: D&I | F26: Transactional | G26: Firm | H26: Concluded | I26: February-26 | J26: 2025 | K26: 100 | L26: 1 | N26: =($K26*$D26)/$L26 -> 100
A27: Pressure Control | B27: Ram Block | C27: CON - Ram Block - Constellation - 470004599 (From by sales) | D27: 1 | E27: D&I | F27: Transactional | G27: Firm | H27: Concluded | I27: February-26 | J27: 2025 | K27: 100 | L27: 1 | N27: =($K27*$D27)/$L27 -> 100
A28: Pressure Control | B28: Ram Block | C28: CON - Ram Block - Constellation - 470004600 (From by sales) | D28: 1 | E28: D&I | F28: Transactional | G28: Firm | H28: Concluded | I28: February-26 | J28: 2025 | K28: 100 | L28: 1 | N28: =($K28*$D28)/$L28 -> 100
A29: Pressure Control | B29: Ram Block | C29: CON - Ram Block - Constellation - 470004099 (From by Project) | D29: 1 | E29: FPA | F29: FPA | G29: Firm | H29: Concluded | I29: February-26 | J29: 2025 | K29: 386 | L29: 2 | O29: =($K29*$D29)/$L29 -> 193 | P29: =($K29*$D29)/$L29 -> 193
A30: Pressure Control | B30: Ram Block | C30: CON - Ram Block - Constellation - 470004598 (From by Project) | D30: 1 | E30: Repair | F30: Transactional | G30: Firm | H30: Concluded | I30: February-26 | J30: 2025 | K30: 400 | L30: 4 | R30: =($K30*$D30)/$L30 -> 100 | S30: 200 | T30: 67 | U30: 33
A31: Pressure Control | B31: Ram Block | C31: CON - Ram Block - Constellation - 470004599 (From by Project) | D31: 1 | E31: Repair | F31: Transactional | G31: Firm | H31: Concluded | I31: February-26 | J31: 2025 | K31: 440 | L31: 6 | Q31: 88 | R31: 72 | S31: 150 | T31: 50 | U31: 40 | V31: 40
A32: Pressure Control | B32: Ram Block | C32: CON - Ram Block - Constellation - 470004600 (From by Project) | D32: 1 | E32: Repair | F32: Transactional | G32: Firm | H32: Concluded | I32: February-26 | J32: 2025 | K32: 440 | L32: 5 | R32: 100 | S32: 200 | T32: 67 | U32: 33 | V32: 40
A33: Pressure Control | B33: Ram Block | C33: CON - Ram Block - Constellation - 470004100 (From by Project) | D33: 1 | E33: FPA | F33: FPA | G33: Firm | H33: Concluded | I33: February-26 | J33: 2025 | K33: 386 | L33: 3 | O33: =($K33*$D33)/$L33 -> 128.66667 | P33: =($K33*$D33)/$L33 -> 128.66667 | Q33: =($K33*$D33)/$L33 -> 128.66667
A34: Riser | B34: Riser Joint - FT - H | C34: 35J Inspeção Laguna Star, do lote de 41J | D34: 35 | E34: CSA | F34: Short Cycle | G34: Firm | H34: Concluded | I34: February-26 | J34: 2025 | K34: 64 | L34: 4 | Q34: 142 | R34: 1443 | S34: 448 | T34: 200
A35: Riser | B35: Riser Joint - FT - H | C35: 6J Inspeção Laguna Star, pendentes do lote de 41J | D35: 6 | E35: CSA | F35: Short Cycle | G35: Firm | H35: Concluded | I35: February-26 | J35: 2025 | K35: 45 | L35: 1 | V35: =($K35*$D35)/$L35 -> 270
A36: Riser | B36: Riser Joint - FT - H | C36: 25J Montagem laguna Star com Amaralina | D36: 25 | E36: CSA | F36: Short Cycle | G36: Firm | H36: Concluded | I36: February-26 | J36: 2025 | K36: 150 | L36: 1 | U36: =($K36*$D36)/$L36 -> 3750
A37: Riser | B37: Riser Joint - FT - H | C37: 7J teste/montagem Laguna Star - Minor Repair | D37: 7 | E37: CSA | F37: Short Cycle | G37: Firm | H37: Concluded | I37: February-26 | J37: 2025 | K37: 150 | L37: 1 | V37: =($K37*$D37)/$L37 -> 1050
A38: Riser | B38: Riser Joint - FT - H | C38: 17J Inspeção Amaralina Star, do lote de 34J | D38: 17 | E38: CSA | F38: Short Cycle | G38: Firm | H38: Concluded | I38: February-26 | J38: 2025 | K38: 64 | L38: 3 | Q38: 113 | R38: 720 | S38: 264
A39: Riser | B39: Riser Joint - FT - H | C39: 24J Inspeção Amaralina Star | D39: 24 | E39: CSA | F39: Short Cycle | G39: Firm | H39: Concluded | I39: February-26 | J39: 2025 | K39: 45 | L39: 1 | V39: =($K39*$D39)/$L39 -> 1080
A40: Riser | B40: Riser Joint - FT - H | C40: 39J SPS Inspeção Amaralina Star, juntas que virão para onshore | D40: 39 | E40: CSA | F40: Short Cycle | G40: Firm | H40: WIP | I40: January-26 | J40: 2026 | K40: 150 | L40: 1 | Y40: =($K40*$D40)/$L40 -> 5850
...

Sheet RCCP SAM
BE3: CATEGORY | BF3: 2025 Demand | BG3: 2026 Demand | BH3: 2027 Demand
A4: Product Line | B4: Equipment | C4: Type | D4: 2025 - Demand (Volumes) | P4: 2026 - Demand (Volumes) | AB4: 2027 - Demand (Volumes) | BE4: O&R RISER FIRM | BF4: =SUM(AQ44:AT44)/1000 -> 82.966267 | BG4: =SUM(AU44:AX44)/1000 -> 63.6976 | BH4: =SUM(AY44:BB44)/1000 -> 38.2468
D5: January-25 | E5: February-25 | F5: March-25 | G5: April-25 | H5: May-25 | I5: June-25 | J5: July-25 | K5: August-25 | L5: September-25 | M5: October-25 | N5: November-25 | O5: December-25 | P5: January-26 | Q5: February-26 | R5: March-26 | S5: April-26 | T5: May-26 | U5: June-26 | V5: July-26 | W5: August-26 | X5: September-26 | Y5: October-26 | Z5: November-26 | AA5: December-26 | AB5: January-27 | AC5: February-27 | AD5: March-27 | AE5: April-27 | AF5: May-27 | AG5: June-27 | AH5: July-27 | AI5: August-27 | AJ5: September-27 | AK5: October-27 | AL5: November-27 | AM5: December-27 | BE5: O&R RISER RISK RELEASE | BF5: =SUM(AQ48:AT48)/1000 -> 0 | BG5: =SUM(AU48:AX48)/1000 -> 0 | BH5: =SUM(AY48:BB48)/1000 -> 0
A6: Pressure Control | B6: H4 Connector | C6: Firm | D6: 2129.6 | E6: 1777.6 | F6: 445.1 | G6: 251.5 | H6: 735.5 | I6: {=SUMPRODUCT(('Projects Overview'!$B$2:$B$5021="H4 Connector")*('Projects Overview'!$G$2:$G$5021="Firm")*('Projects Overview'!R$2:R$5021))} -> 522.85714 | J6: {=SUMPRODUCT(('Projects Overview'!$B$2:$B$5021="H4 Connector")*('Projects Overview'!$G$2:$G$5021="Firm")*('Projects Overview'!S$2:S$5021))} -> 152 | K6: {=SUMPRODUCT(('Projects Overview'!$B$2:$B$5021="H4 Connector")*('Projects Overview'!$G$2:$G$5021="Firm")*('Projects Overview'!T$2:T$5021))} -> 822.66667 | L6: {=SUMPRODUCT(('Projects Overview'!$B$2:$B$5021="H4 Connector")*('Projects Overview'!$G$2:$G$5021="Firm")*('Projects Overview'!U$2:U$5021))} -> 782.66667 | M6: {=SUMPRODUCT(('Projects Overview'!$B$2:$B$5021="H4 Connector")*('Projects Overview'!$G$2:$G$5021="Firm")*('Projects Overview'!V$2:V$5021))} -> 1341.6667 | N6: {=SUMPRODUCT(('Projects Overview'!$B$2:$B$5021="H4 Connector")*('Projects Overview'!$G$2:$G$5021="Firm")*('Projects Overview'!W$2:W$5021))} -> 1920.6667 | O6: {=SUMPRODUCT(('Projects Overview'!$B$2:$B$5021="H4 Connector")*('Projects Overview'!$G$2:$G$5021="Firm")*('Projects Overview'!X$2:X$5021))} -> 764 | P6: {=SUMPRODUCT(('Projects Overview'!$B$2:$B$5021="H4 Connector")*('Projects Overview'!$G$2:$G$5021="Firm")*('Projects Overview'!Y$2:Y$5021))} -> 638 | ... AM6: {=SUMPRODUCT(('Projects Overview'!$B$2:$B$5021="H4 Connector")*('Projects Overview'!$G$2:$G$5021="Firm")*('Projects Overview'!AV$2:AV$5021))} -> 0 | BE6: O&R RISER FCST | BF6: =SUM(AQ52:AT52)/1000 -> 0 | BG6: =SUM(AU52:AX52)/1000 -> 19.302 | BH6: =SUM(AY52:BB52)/1000 -> 0
C7: Risk Release | D7: 0 | E7: 0 | F7: 0 | G7: 0 | H7: 0 | I7: {=SUMPRODUCT(('Projects Overview'!$B$2:$B$5021="H4 Connector")*('Projects Overview'!$G$2:$G$5021="Risk Release")*('Projects Overview'!R$2:R$5021))} -> 0 | J7: {=SUMPRODUCT(('Projects Overview'!$B$2:$B$5021="H4 Connector")*('Projects Overview'!$G$2:$G$5021="Risk Release")*('Projects Overview'!S$2:S$5021))} -> 0 | K7: {=SUMPRODUCT(('Projects Overview'!$B$2:$B$5021="H4 Connector")*('Projects Overview'!$G$2:$G$5021="Risk Release")*('Projects Overview'!T$2:T$5021))} -> 0 | L7: {=SUMPRODUCT(('Projects Overview'!$B$2:$B$5021="H4 Connector")*('Projects Overview'!$G$2:$G$5021="Risk Release")*('Projects Overview'!U$2:U$5021))} -> 0 | M7: {=SUMPRODUCT(('Projects Overview'!$B$2:$B$5021="H4 Connector")*('Projects Overview'!$G$2:$G$5021="Risk Release")*('Projects Overview'!V$2:V$5021))} -> 0 | N7: {=SUMPRODUCT(('Projects Overview'!$B$2:$B$5021="H4 Connector")*('Projects Overview'!$G$2:$G$5021="Risk Release")*('Projects Overview'!W$2:W$5021))} -> 0 | O7: {=SUMPRODUCT(('Projects Overview'!$B$2:$B$5021="H4 Connector")*('Projects Overview'!$G$2:$G$5021="Risk Release")*('Projects Overview'!X$2:X$5021))} -> 0 | P7: {=SUMPRODUCT(('Projects Overview'!$B$2:$B$5021="H4 Connector")*('Projects Overview'!$G$2:$G$5021="Risk Release")*('Projects Overview'!Y$2:Y$5021))} -> 0 | ... AM7: {=SUMPRODUCT(('Projects Overview'!$B$2:$B$5021="H4 Connector")*('Projects Overview'!$G$2:$G$5021="Risk Release")*('Projects Overview'!AV$2:AV$5021))} -> 0 | BE7: O&R RISER TOTAL Hrs. | BF7: =SUM(BF4:BF6) -> 82.966267 | BG7: =SUM(BG4:BG6) -> 82.9996 | BH7: =SUM(BH4:BH6) -> 38.2468
C8: Forecast | D8: 0 | E8: 0 | F8: 0 | G8: 0 | H8: 0 | I8: {=SUMPRODUCT(('Projects Overview'!$B$2:$B$5021="H4 Connector")*('Projects Overview'!$G$2:$G$5021="Forecast")*('Projects Overview'!R$2:R$5021))} -> 0 | J8: {=SUMPRODUCT(('Projects Overview'!$B$2:$B$5021="H4 Connector")*('Projects Overview'!$G$2:$G$5021="Forecast")*('Projects Overview'!S$2:S$5021))} -> 0 | K8: {=SUMPRODUCT(('Projects Overview'!$B$2:$B$5021="H4 Connector")*('Projects Overview'!$G$2:$G$5021="Forecast")*('Projects Overview'!T$2:T$5021))} -> 0 | L8: {=SUMPRODUCT(('Projects Overview'!$B$2:$B$5021="H4 Connector")*('Projects Overview'!$G$2:$G$5021="Forecast")*('Projects Overview'!U$2:U$5021))} -> 0 | M8: {=SUMPRODUCT(('Projects Overview'!$B$2:$B$5021="H4 Connector")*('Projects Overview'!$G$2:$G$5021="Forecast")*('Projects Overview'!V$2:V$5021))} -> 0 | N8: {=SUMPRODUCT(('Projects Overview'!$B$2:$B$5021="H4 Connector")*('Projects Overview'!$G$2:$G$5021="Forecast")*('Projects Overview'!W$2:W$5021))} -> 0 | O8: {=SUMPRODUCT(('Projects Overview'!$B$2:$B$5021="H4 Connector")*('Projects Overview'!$G$2:$G$5021="Forecast")*('Projects Overview'!X$2:X$5021))} -> 0 | P8: {=SUMPRODUCT(('Projects Overview'!$B$2:$B$5021="H4 Connector")*('Projects Overview'!$G$2:$G$5021="Forecast")*('Projects Overview'!Y$2:Y$5021))} -> 0 | ... AM8: {=SUMPRODUCT(('Projects Overview'!$B$2:$B$5021="H4 Connector")*('Projects Overview'!$G$2:$G$5021="Forecast")*('Projects Overview'!AV$2:AV$5021))} -> 0 | BE8: O&R TOPSIDE FIRM | BF8: =SUM(AQ46:AT46)/1000 -> 23.927595 | BG8: =SUM(AU46:AX46)/1000 -> 3.854 | BH8: =SUM(AY46:BB46)/1000 -> 0
B9: Bonnet | C9: Firm | D9: 211.2 | E9: 821.86667 | F9: 973.86667 | G9: 762.66667 | H9: 352 | I9: {=SUMPRODUCT(('Projects Overview'!$B$2:$B$5021="Bonnet")*('Projects Overview'!$G$2:$G$5021="Firm")*('Projects Overview'!R$2:R$5021))} -> 544 | J9: {=SUMPRODUCT(('Projects Overview'!$B$2:$B$5021="Bonnet")*('Projects Overview'!$G$2:$G$5021="Firm")*('Projects Overview'!S$2:S$5021))} -> 400 | K9: {=SUMPRODUCT(('Projects Overview'!$B$2:$B$5021="Bonnet")*('Projects Overview'!$G$2:$G$5021="Firm")*('Projects Overview'!T$2:T$5021))} -> 400 | L9: {=SUMPRODUCT(('Projects Overview'!$B$2:$B$5021="Bonnet")*('Projects Overview'!$G$2:$G$5021="Firm")*('Projects Overview'!U$2:U$5021))} -> 522 | M9: {=SUMPRODUCT(('Projects Overview'!$B$2:$B$5021="Bonnet")*('Projects Overview'!$G$2:$G$5021="Firm")*('Projects Overview'!V$2:V$5021))} -> 668 | N9: {=SUMPRODUCT(('Projects Overview'!$B$2:$B$5021="Bonnet")*('Projects Overview'!$G$2:$G$5021="Firm")*('Projects Overview'!W$2:W$5021))} -> 600 | O9: {=SUMPRODUCT(('Projects Overview'!$B$2:$B$5021="Bonnet")*('Projects Overview'!$G$2:$G$5021="Firm")*('Projects Overview'!X$2:X$5021))} -> 300 | P9: {=SUMPRODUCT(('Projects Overview'!$B$2:$B$5021="Bonnet")*('Projects Overview'!$G$2:$G$5021="Firm")*('Projects Overview'!Y$2:Y$5021))} -> 120 | ... AM9: {=SUMPRODUCT(('Projects Overview'!$B$2:$B$5021="Bonnet")*('Projects Overview'!$G$2:$G$5021="Firm")*('Projects Overview'!AV$2:AV$5021))} -> 0 | BE9: O&R TOPSIDE RISK RELEASE | BF9: =SUM(AQ50:AT50)/1000 -> 0 | BG9: =SUM(AU50:AX50)/1000 -> 0 | BH9: =SUM(AY50:BB50)/1000 -> 0
C10: Risk Release | D10: 0 | E10: 0 | F10: 0 | G10: 0 | H10: 0 | I10: {=SUMPRODUCT(('Projects Overview'!$B$2:$B$5021="Bonnet")*('Projects Overview'!$G$2:$G$5021="Risk Release")*('Projects Overview'!R$2:R$5021))} -> 0 | J10: {=SUMPRODUCT(('Projects Overview'!$B$2:$B$5021="Bonnet")*('Projects Overview'!$G$2:$G$5021="Risk Release")*('Projects Overview'!S$2:S$5021))} -> 0 | K10: {=SUMPRODUCT(('Projects Overview'!$B$2:$B$5021="Bonnet")*('Projects Overview'!$G$2:$G$5021="Risk Release")*('Projects Overview'!T$2:T$5021))} -> 0 | L10: {=SUMPRODUCT(('Projects Overview'!$B$2:$B$5021="Bonnet")*('Projects Overview'!$G$2:$G$5021="Risk Release")*('Projects Overview'!U$2:U$5021))} -> 0 | M10: {=SUMPRODUCT(('Projects Overview'!$B$2:$B$5021="Bonnet")*('Projects Overview'!$G$2:$G$5021="Risk Release")*('Projects Overview'!V$2:V$5021))} -> 0 | N10: {=SUMPRODUCT(('Projects Overview'!$B$2:$B$5021="Bonnet")*('Projects Overview'!$G$2:$G$5021="Risk Release")*('Projects Overview'!W$2:W$5021))} -> 0 | O10: {=SUMPRODUCT(('Projects Overview'!$B$2:$B$5021="Bonnet")*('Projects Overview'!$G$2:$G$5021="Risk Release")*('Projects Overview'!X$2:X$5021))} -> 0 | P10: {=SUMPRODUCT(('Projects Overview'!$B$2:$B$5021="Bonnet")*('Projects Overview'!$G$2:$G$5021="Risk Release")*('Projects Overview'!Y$2:Y$5021))} -> 0 | ... AM10: {=SUMPRODUCT(('Projects Overview'!$B$2:$B$5021="Bonnet")*('Projects Overview'!$G$2:$G$5021="Risk Release")*('Projects Overview'!AV$2:AV$5021))} -> 0 | BE10: O&R TOPSIDE FCST | BF10: =SUM(AQ54:AT54)/1000 -> 0 | BG10: =SUM(AU54:AX54)/1000 -> 13.684 | BH10: =SUM(AY54:BB54)/1000 -> 1.9166667
C11: Forecast | D11: 0 | E11: 0 | F11: 0 | G11: 0 | H11: 0 | I11: {=SUMPRODUCT(('Projects Overview'!$B$2:$B$5021="Bonnet")*('Projects Overview'!$G$2:$G$5021="Forecast")*('Projects Overview'!R$2:R$5021))} -> 0 | J11: {=SUMPRODUCT(('Projects Overview'!$B$2:$B$5021="Bonnet")*('Projects Overview'!$G$2:$G$5021="Forecast")*('Projects Overview'!S$2:S$5021))} -> 0 | K11: {=SUMPRODUCT(('Projects Overview'!$B$2:$B$5021="Bonnet")*('Projects Overview'!$G$2:$G$5021="Forecast")*('Projects Overview'!T$2:T$5021))} -> 0 | L11: {=SUMPRODUCT(('Projects Overview'!$B$2:$B$5021="Bonnet")*('Projects Overview'!$G$2:$G$5021="Forecast")*('Projects Overview'!U$2:U$5021))} -> 0 | M11: {=SUMPRODUCT(('Projects Overview'!$B$2:$B$5021="Bonnet")*('Projects Overview'!$G$2:$G$5021="Forecast")*('Projects Overview'!V$2:V$5021))} -> 0 | N11: {=SUMPRODUCT(('Projects Overview'!$B$2:$B$5021="Bonnet")*('Projects Overview'!$G$2:$G$5021="Forecast")*('Projects Overview'!W$2:W$5021))} -> 0 | O11: {=SUMPRODUCT(('Projects Overview'!$B$2:$B$5021="Bonnet")*('Projects Overview'!$G$2:$G$5021="Forecast")*('Projects Overview'!X$2:X$5021))} -> 0 | P11: {=SUMPRODUCT(('Projects Overview'!$B$2:$B$5021="Bonnet")*('Projects Overview'!$G$2:$G$5021="Forecast")*('Projects Overview'!Y$2:Y$5021))} -> 0 | ... AM11: {=SUMPRODUCT(('Projects Overview'!$B$2:$B$5021="Bonnet")*('Projects Overview'!$G$2:$G$5021="Forecast")*('Projects Overview'!AV$2:AV$5021))} -> 0 | BE11: O&R TOPSIDE TOTAL Hrs. | BF11: =SUM(BF8:BF10) -> 23.927595 | BG11: =SUM(BG8:BG10) -> 17.538 | BH11: =SUM(BH8:BH10) -> 1.9166667
B12: BOP Annular | C12: Firm | D12: 261.6 | E12: 261.6 | F12: 261.6 | G12: 0 | H12: 0 | I12: {=SUMPRODUCT(('Projects Overview'!$B$2:$B$5021="BOP Annular")*('Projects Overview'!$G$2:$G$5021="Firm")*('Projects Overview'!R$2:R$5021))} -> 0 | J12: {=SUMPRODUCT(('Projects Overview'!$B$2:$B$5021="BOP Annular")*('Projects Overview'!$G$2:$G$5021="Firm")*('Projects Overview'!S$2:S$5021))} -> 0 | K12: {=SUMPRODUCT(('Projects Overview'!$B$2:$B$5021="BOP Annular")*('Projects Overview'!$G$2:$G$5021="Firm")*('Projects Overview'!T$2:T$5021))} -> 0 | L12: {=SUMPRODUCT(('Projects Overview'!$B$2:$B$5021="BOP Annular")*('Projects Overview'!$G$2:$G$5021="Firm")*('Projects Overview'!U$2:U$5021))} -> 0 | M12: {=SUMPRODUCT(('Projects Overview'!$B$2:$B$5021="BOP Annular")*('Projects Overview'!$G$2:$G$5021="Firm")*('Projects Overview'!V$2:V$5021))} -> 0 | N12: {=SUMPRODUCT(('Projects Overview'!$B$2:$B$5021="BOP Annular")*('Projects Overview'!$G$2:$G$5021="Firm")*('Projects Overview'!W$2:W$5021))} -> 296 | O12: {=SUMPRODUCT(('Projects Overview'!$B$2:$B$5021="BOP Annular")*('Projects Overview'!$G$2:$G$5021="Firm")*('Projects Overview'!X$2:X$5021))} -> 20 | P12: {=SUMPRODUCT(('Projects Overview'!$B$2:$B$5021="BOP Annular")*('Projects Overview'!$G$2:$G$5021="Firm")*('Projects Overview'!Y$2:Y$5021))} -> 270 | ... AM12: {=SUMPRODUCT(('Projects Overview'!$B$2:$B$5021="BOP Annular")*('Projects Overview'!$G$2:$G$5021="Firm")*('Projects Overview'!AV$2:AV$5021))} -> 0 | BE12: O&R PRESSURE CONTROL FIRM | BF12: =SUM(AQ45:AT45)/1000 -> 29.46039 | BG12: =SUM(AU45:AX45)/1000 -> 4.708 | BH12: =SUM(AY45:BB45)/1000 -> 0
C13: Risk Release | D13: 0 | E13: 0 | F13: 0 | G13: 0 | H13: 0 | I13: {=SUMPRODUCT(('Projects Overview'!$B$2:$B$5021="BOP Annular")*('Projects Overview'!$G$2:$G$5021="Risk Release")*('Projects Overview'!R$2:R$5021))} -> 0 | J13: {=SUMPRODUCT(('Projects Overview'!$B$2:$B$5021="BOP Annular")*('Projects Overview'!$G$2:$G$5021="Risk Release")*('Projects Overview'!S$2:S$5021))} -> 0 | K13: {=SUMPRODUCT(('Projects Overview'!$B$2:$B$5021="BOP Annular")*('Projects Overview'!$G$2:$G$5021="Risk Release")*('Projects Overview'!T$2:T$5021))} -> 0 | L13: {=SUMPRODUCT(('Projects Overview'!$B$2:$B$5021="BOP Annular")*('Projects Overview'!$G$2:$G$5021="Risk Release")*('Projects Overview'!U$2:U$5021))} -> 0 | M13: {=SUMPRODUCT(('Projects Overview'!$B$2:$B$5021="BOP Annular")*('Projects Overview'!$G$2:$G$5021="Risk Release")*('Projects Overview'!V$2:V$5021))} -> 0 | N13: {=SUMPRODUCT(('Projects Overview'!$B$2:$B$5021="BOP Annular")*('Projects Overview'!$G$2:$G$5021="Risk Release")*('Projects Overview'!W$2:W$5021))} -> 0 | O13: {=SUMPRODUCT(('Projects Overview'!$B$2:$B$5021="BOP Annular")*('Projects Overview'!$G$2:$G$5021="Risk Release")*('Projects Overview'!X$2:X$5021))} -> 0 | P13: {=SUMPRODUCT(('Projects Overview'!$B$2:$B$5021="BOP Annular")*('Projects Overview'!$G$2:$G$5021="Risk Release")*('Projects Overview'!Y$2:Y$5021))} -> 0 | ... AM13: {=SUMPRODUCT(('Projects Overview'!$B$2:$B$5021="BOP Annular")*('Projects Overview'!$G$2:$G$5021="Risk Release")*('Projects Overview'!AV$2:AV$5021))} -> 0 | BE13: O&R PRESSURE CONTROL RISK RELEASE | BF13: =SUM(AQ50:AT50)/1000 -> 0 | BG13: =SUM(AU50:AX50)/1000 -> 0 | BH13: =SUM(AY50:BB50)/1000 -> 0
C14: Forecast | D14: 0 | E14: 0 | F14: 0 | G14: 0 | H14: 0 | I14: {=SUMPRODUCT(('Projects Overview'!$B$2:$B$5021="BOP Annular")*('Projects Overview'!$G$2:$G$5021="Forecast")*('Projects Overview'!R$2:R$5021))} -> 0 | J14: {=SUMPRODUCT(('Projects Overview'!$B$2:$B$5021="BOP Annular")*('Projects Overview'!$G$2:$G$5021="Forecast")*('Projects Overview'!S$2:S$5021))} -> 0 | K14: {=SUMPRODUCT(('Projects Overview'!$B$2:$B$5021="BOP Annular")*('Projects Overview'!$G$2:$G$5021="Forecast")*('Projects Overview'!T$2:T$5021))} -> 0 | L14: {=SUMPRODUCT(('Projects Overview'!$B$2:$B$5021="BOP Annular")*('Projects Overview'!$G$2:$G$5021="Forecast")*('Projects Overview'!U$2:U$5021))} -> 0 | M14: {=SUMPRODUCT(('Projects Overview'!$B$2:$B$5021="BOP Annular")*('Projects Overview'!$G$2:$G$5021="Forecast")*('Projects Overview'!V$2:V$5021))} -> 0 | N14: {=SUMPRODUCT(('Projects Overview'!$B$2:$B$5021="BOP Annular")*('Projects Overview'!$G$2:$G$5021="Forecast")*('Projects Overview'!W$2:W$5021))} -> 0 | O14: {=SUMPRODUCT(('Projects Overview'!$B$2:$B$5021="BOP Annular")*('Projects Overview'!$G$2:$G$5021="Forecast")*('Projects Overview'!X$2:X$5021))} -> 0 | P14: {=SUMPRODUCT(('Projects Overview'!$B$2:$B$5021="BOP Annular")*('Projects Overview'!$G$2:$G$5021="Forecast")*('Projects Overview'!Y$2:Y$5021))} -> 0 | ... AM14: {=SUMPRODUCT(('Projects Overview'!$B$2:$B$5021="BOP Annular")*('Projects Overview'!$G$2:$G$5021="Forecast")*('Projects Overview'!AV$2:AV$5021))} -> 0 | BE14: O&R PRESSURE CONTROL FCST | BF14: =SUM(AQ53:AT53)/1000 -> 0 | BG14: =SUM(AU53:AX53)/1000 -> 12.124 | BH14: =SUM(AY53:BB53)/1000 -> 2.5
B15: Annular Piston | C15: Firm | D15: 424.16667 | E15: 256.66667 | F15: 256.66667 | G15: 256.66667 | H15: 0 | I15: {=SUMPRODUCT(('Projects Overview'!$B$2:$B$5021="Annular Piston")*('Projects Overview'!$G$2:$G$5021="Firm")*('Projects Overview'!R$2:R$5021))} -> 0 | J15: {=SUMPRODUCT(('Projects Overview'!$B$2:$B$5021="Annular Piston")*('Projects Overview'!$G$2:$G$5021="Firm")*('Projects Overview'!S$2:S$5021))} -> 0 | K15: {=SUMPRODUCT(('Projects Overview'!$B$2:$B$5021="Annular Piston")*('Projects Overview'!$G$2:$G$5021="Firm")*('Projects Overview'!T$2:T$5021))} -> 0 | L15: {=SUMPRODUCT(('Projects Overview'!$B$2:$B$5021="Annular Piston")*('Projects Overview'!$G$2:$G$5021="Firm")*('Projects Overview'!U$2:U$5021))} -> 0 | M15: {=SUMPRODUCT(('Projects Overview'!$B$2:$B$5021="Annular Piston")*('Projects Overview'!$G$2:$G$5021="Firm")*('Projects Overview'!V$2:V$5021))} -> 0 | N15: {=SUMPRODUCT(('Projects Overview'!$B$2:$B$5021="Annular Piston")*('Projects Overview'!$G$2:$G$5021="Firm")*('Projects Overview'!W$2:W$5021))} -> 0 | O15: {=SUMPRODUCT(('Projects Overview'!$B$2:$B$5021="Annular Piston")*('Projects Overview'!$G$2:$G$5021="Firm")*('Projects Overview'!X$2:X$5021))} -> 0 | P15: {=SUMPRODUCT(('Projects Overview'!$B$2:$B$5021="Annular Piston")*('Projects Overview'!$G$2:$G$5021="Firm")*('Projects Overview'!Y$2:Y$5021))} -> 0 | ... AM15: {=SUMPRODUCT(('Projects Overview'!$B$2:$B$5021="Annular Piston")*('Projects Overview'!$G$2:$G$5021="Firm")*('Projects Overview'!AV$2:AV$5021))} -> 0 | BE15: O&R PRESSURE CONTROL TOTAL Hrs. | BF15: =SUM(BF12:BF14) -> 29.46039 | BG15: =SUM(BG12:BG14) -> 16.832 | BH15: =SUM(BH12:BH14) -> 2.5
C16: Risk Release | D16: 0 | E16: 0 | F16: 0 | G16: 0 | H16: 0 | I16: {=SUMPRODUCT(('Projects Overview'!$B$2:$B$5021="Annular Piston")*('Projects Overview'!$G$2:$G$5021="Risk Release")*('Projects Overview'!R$2:R$5021))} -> 0 | J16: {=SUMPRODUCT(('Projects Overview'!$B$2:$B$5021="Annular Piston")*('Projects Overview'!$G$2:$G$5021="Risk Release")*('Projects Overview'!S$2:S$5021))} -> 0 | K16: {=SUMPRODUCT(('Projects Overview'!$B$2:$B$5021="Annular Piston")*('Projects Overview'!$G$2:$G$5021="Risk Release")*('Projects Overview'!T$2:T$5021))} -> 0 | L16: {=SUMPRODUCT(('Projects Overview'!$B$2:$B$5021="Annular Piston")*('Projects Overview'!$G$2:$G$5021="Risk Release")*('Projects Overview'!U$2:U$5021))} -> 0 | M16: {=SUMPRODUCT(('Projects Overview'!$B$2:$B$5021="Annular Piston")*('Projects Overview'!$G$2:$G$5021="Risk Release")*('Projects Overview'!V$2:V$5021))} -> 0 | N16: {=SUMPRODUCT(('Projects Overview'!$B$2:$B$5021="Annular Piston")*('Projects Overview'!$G$2:$G$5021="Risk Release")*('Projects Overview'!W$2:W$5021))} -> 0 | O16: {=SUMPRODUCT(('Projects Overview'!$B$2:$B$5021="Annular Piston")*('Projects Overview'!$G$2:$G$5021="Risk Release")*('Projects Overview'!X$2:X$5021))} -> 0 | P16: {=SUMPRODUCT(('Projects Overview'!$B$2:$B$5021="Annular Piston")*('Projects Overview'!$G$2:$G$5021="Risk Release")*('Projects Overview'!Y$2:Y$5021))} -> 0 | ... AM16: {=SUMPRODUCT(('Projects Overview'!$B$2:$B$5021="Annular Piston")*('Projects Overview'!$G$2:$G$5021="Risk Release")*('Projects Overview'!AV$2:AV$5021))} -> 0 | BE16: OTHERS FIRM | BF16: =SUM(AQ47:AT47)/1000 -> 8.074 | BG16: =SUM(AU47:AX47)/1000 -> 1.4 | BH16: =SUM(AY47:BB47)/1000 -> 0
C17: Forecast | D17: 0 | E17: 0 | F17: 0 | G17: 0 | H17: 0 | I17: {=SUMPRODUCT(('Projects Overview'!$B$2:$B$5021="Annular Piston")*('Projects Overview'!$G$2:$G$5021="Forecast")*('Projects Overview'!R$2:R$5021))} -> 0 | J17: {=SUMPRODUCT(('Projects Overview'!$B$2:$B$5021="Annular Piston")*('Projects Overview'!$G$2:$G$5021="Forecast")*('Projects Overview'!S$2:S$5021))} -> 0 | K17: {=SUMPRODUCT(('Projects Overview'!$B$2:$B$5021="Annular Piston")*('Projects Overview'!$G$2:$G$5021="Forecast")*('Projects Overview'!T$2:T$5021))} -> 0 | L17: {=SUMPRODUCT(('Projects Overview'!$B$2:$B$5021="Annular Piston")*('Projects Overview'!$G$2:$G$5021="Forecast")*('Projects Overview'!U$2:U$5021))} -> 0 | M17: {=SUMPRODUCT(('Projects Overview'!$B$2:$B$5021="Annular Piston")*('Projects Overview'!$G$2:$G$5021="Forecast")*('Projects Overview'!V$2:V$5021))} -> 0 | N17: {=SUMPRODUCT(('Projects Overview'!$B$2:$B$5021="Annular Piston")*('Projects Overview'!$G$2:$G$5021="Forecast")*('Projects Overview'!W$2:W$5021))} -> 0 | O17: {=SUMPRODUCT(('Projects Overview'!$B$2:$B$5021="Annular Piston")*('Projects Overview'!$G$2:$G$5021="Forecast")*('Projects Overview'!X$2:X$5021))} -> 0 | P17: {=SUMPRODUCT(('Projects Overview'!$B$2:$B$5021="Annular Piston")*('Projects Overview'!$G$2:$G$5021="Forecast")*('Projects Overview'!Y$2:Y$5021))} -> 0 | ... AM17: {=SUMPRODUCT(('Projects Overview'!$B$2:$B$5021="Annular Piston")*('Projects Overview'!$G$2:$G$5021="Forecast")*('Projects Overview'!AV$2:AV$5021))} -> 0 | BE17: O&R OTHERS RISK RELEASE | BF17: =SUM(AQ51:AT51)/1000 -> 0 | BG17: =SUM(AU51:AX51)/1000 -> 0 | BH17: =SUM(AY51:BB51)/1000 -> 0
B18: Male Stab | C18: Firm | D18: 0 | E18: 0 | F18: 0 | G18: 0 | H18: 0 | I18: {=SUMPRODUCT(('Projects Overview'!$B$2:$B$5021="Male Stab")*('Projects Overview'!$G$2:$G$5021="Firm")*('Projects Overview'!R$2:R$5021))} -> 0 | J18: {=SUMPRODUCT(('Projects Overview'!$B$2:$B$5021="Male Stab")*('Projects Overview'!$G$2:$G$5021="Firm")*('Projects Overview'!S$2:S$5021))} -> 0 | K18: {=SUMPRODUCT(('Projects Overview'!$B$2:$B$5021="Male Stab")*('Projects Overview'!$G$2:$G$5021="Firm")*('Projects Overview'!T$2:T$5021))} -> 0 | L18: {=SUMPRODUCT(('Projects Overview'!$B$2:$B$5021="Male Stab")*('Projects Overview'!$G$2:$G$5021="Firm")*('Projects Overview'!U$2:U$5021))} -> 0 | M18: {=SUMPRODUCT(('Projects Overview'!$B$2:$B$5021="Male Stab")*('Projects Overview'!$G$2:$G$5021="Firm")*('Projects Overview'!V$2:V$5021))} -> 0 | N18: {=SUMPRODUCT(('Projects Overview'!$B$2:$B$5021="Male Stab")*('Projects Overview'!$G$2:$G$5021="Firm")*('Projects Overview'!W$2:W$5021))} -> 0 | O18: {=SUMPRODUCT(('Projects Overview'!$B$2:$B$5021="Male Stab")*('Projects Overview'!$G$2:$G$5021="Firm")*('Projects Overview'!X$2:X$5021))} -> 0 | P18: {=SUMPRODUCT(('Projects Overview'!$B$2:$B$5021="Male Stab")*('Projects Overview'!$G$2:$G$5021="Firm")*('Projects Overview'!Y$2:Y$5021))} -> 0 | ... AM18: {=SUMPRODUCT(('Projects Overview'!$B$2:$B$5021="Male Stab")*('Projects Overview'!$G$2:$G$5021="Firm")*('Projects Overview'!AV$2:AV$5021))} -> 0 | BE18: OTHERS FCST | BF18: =SUM(AQ55:AT55)/1000 -> 0 | BG18: =SUM(AU55:AX55)/1000 -> 6.19 | BH18: =SUM(AY55:BB55)/1000 -> 0
C19: Risk Release | D19: 0 | E19: 0 | F19: 0 | G19: 0 | H19: 0 | I19: {=SUMPRODUCT(('Projects Overview'!$B$2:$B$5021="Male Stab")*('Projects Overview'!$G$2:$G$5021="Risk Release")*('Projects Overview'!R$2:R$5021))} -> 0 | J19: {=SUMPRODUCT(('Projects Overview'!$B$2:$B$5021="Male Stab")*('Projects Overview'!$G$2:$G$5021="Risk Release")*('Projects Overview'!S$2:S$5021))} -> 0 | K19: {=SUMPRODUCT(('Projects Overview'!$B$2:$B$5021="Male Stab")*('Projects Overview'!$G$2:$G$5021="Risk Release")*('Projects Overview'!T$2:T$5021))} -> 0 | L19: {=SUMPRODUCT(('Projects Overview'!$B$2:$B$5021="Male Stab")*('Projects Overview'!$G$2:$G$5021="Risk Release")*('Projects Overview'!U$2:U$5021))} -> 0 | M19: {=SUMPRODUCT(('Projects Overview'!$B$2:$B$5021="Male Stab")*('Projects Overview'!$G$2:$G$5021="Risk Release")*('Projects Overview'!V$2:V$5021))} -> 0 | N19: {=SUMPRODUCT(('Projects Overview'!$B$2:$B$5021="Male Stab")*('Projects Overview'!$G$2:$G$5021="Risk Release")*('Projects Overview'!W$2:W$5021))} -> 0 | O19: {=SUMPRODUCT(('Projects Overview'!$B$2:$B$5021="Male Stab")*('Projects Overview'!$G$2:$G$5021="Risk Release")*('Projects Overview'!X$2:X$5021))} -> 0 | P19: {=SUMPRODUCT(('Projects Overview'!$B$2:$B$5021="Male Stab")*('Projects Overview'!$G$2:$G$5021="Risk Release")*('Projects Overview'!Y$2:Y$5021))} -> 0 | ... AM19: {=SUMPRODUCT(('Projects Overview'!$B$2:$B$5021="Male Stab")*('Projects Overview'!$G$2:$G$5021="Risk Release")*('Projects Overview'!AV$2:AV$5021))} -> 0 | BE19: OTHERS TOTAL Hrs. | BF19: =SUM(BF16:BF18) -> 8.074 | BG19: =SUM(BG16:BG18) -> 7.59 | BH19: =SUM(BH16:BH18) -> 0
C20: Forecast | D20: 0 | E20: 0 | F20: 0 | G20: 0 | H20: 0 | I20: {=SUMPRODUCT(('Projects Overview'!$B$2:$B$5021="Male Stab")*('Projects Overview'!$G$2:$G$5021="Forecast")*('Projects Overview'!R$2:R$5021))} -> 0 | J20: {=SUMPRODUCT(('Projects Overview'!$B$2:$B$5021="Male Stab")*('Projects Overview'!$G$2:$G$5021="Forecast")*('Projects Overview'!S$2:S$5021))} -> 0 | K20: {=SUMPRODUCT(('Projects Overview'!$B$2:$B$5021="Male Stab")*('Projects Overview'!$G$2:$G$5021="Forecast")*('Projects Overview'!T$2:T$5021))} -> 0 | L20: {=SUMPRODUCT(('Projects Overview'!$B$2:$B$5021="Male Stab")*('Projects Overview'!$G$2:$G$5021="Forecast")*('Projects Overview'!U$2:U$5021))} -> 0 | M20: {=SUMPRODUCT(('Projects Overview'!$B$2:$B$5021="Male Stab")*('Projects Overview'!$G$2:$G$5021="Forecast")*('Projects Overview'!V$2:V$5021))} -> 0 | N20: {=SUMPRODUCT(('Projects Overview'!$B$2:$B$5021="Male Stab")*('Projects Overview'!$G$2:$G$5021="Forecast")*('Projects Overview'!W$2:W$5021))} -> 0 | O20: {=SUMPRODUCT(('Projects Overview'!$B$2:$B$5021="Male Stab")*('Projects Overview'!$G$2:$G$5021="Forecast")*('Projects Overview'!X$2:X$5021))} -> 0 | P20: {=SUMPRODUCT(('Projects Overview'!$B$2:$B$5021="Male Stab")*('Projects Overview'!$G$2:$G$5021="Forecast")*('Projects Overview'!Y$2:Y$5021))} -> 0 | ... AM20: {=SUMPRODUCT(('Projects Overview'!$B$2:$B$5021="Male Stab")*('Projects Overview'!$G$2:$G$5021="Forecast")*('Projects Overview'!AV$2:AV$5021))} -> 0 | BE20: TOTAL Hrs. | BF20: =(BF7+BF11+BF15+BF19) -> 144.42825 | BG20: =(BG7+BG11+BG15+BG19) -> 124.9596 | BH20: =(BH7+BH11+BH15+BH19) -> 42.663467
B21: Female Stab | C21: Firm | D21: 0 | E21: 0 | F21: 0 | G21: 124.5 | H21: 0 | I21: {=SUMPRODUCT(('Projects Overview'!$B$2:$B$5021="Female Stab")*('Projects Overview'!$G$2:$G$5021="Firm")*('Projects Overview'!R$2:R$5021))} -> 564.5 | J21: {=SUMPRODUCT(('Projects Overview'!$B$2:$B$5021="Female Stab")*('Projects Overview'!$G$2:$G$5021="Firm")*('Projects Overview'!S$2:S$5021))} -> 0 | K21: {=SUMPRODUCT(('Projects Overview'!$B$2:$B$5021="Female Stab")*('Projects Overview'!$G$2:$G$5021="Firm")*('Projects Overview'!T$2:T$5021))} -> 0 | L21: {=SUMPRODUCT(('Projects Overview'!$B$2:$B$5021="Female Stab")*('Projects Overview'!$G$2:$G$5021="Firm")*('Projects Overview'!U$2:U$5021))} -> 360 | M21: {=SUMPRODUCT(('Projects Overview'!$B$2:$B$5021="Female Stab")*('Projects Overview'!$G$2:$G$5021="Firm")*('Projects Overview'!V$2:V$5021))} -> 360 | N21: {=SUMPRODUCT(('Projects Overview'!$B$2:$B$5021="Female Stab")*('Projects Overview'!$G$2:$G$5021="Firm")*('Projects Overview'!W$2:W$5021))} -> 200 | O21: {=SUMPRODUCT(('Projects Overview'!$B$2:$B$5021="Female Stab")*('Projects Overview'!$G$2:$G$5021="Firm")*('Projects Overview'!X$2:X$5021))} -> 160 | P21: {=SUMPRODUCT(('Projects Overview'!$B$2:$B$5021="Female Stab")*('Projects Overview'!$G$2:$G$5021="Firm")*('Projects Overview'!Y$2:Y$5021))} -> 150 | ... AM21: {=SUMPRODUCT(('Projects Overview'!$B$2:$B$5021="Female Stab")*('Projects Overview'!$G$2:$G$5021="Firm")*('Projects Overview'!AV$2:AV$5021))} -> 0
C22: Risk Release | D22: 0 | E22: 0 | F22: 0 | G22: 0 | H22: 0 | I22: {=SUMPRODUCT(('Projects Overview'!$B$2:$B$5021="Female Stab")*('Projects Overview'!$G$2:$G$5021="Risk Release")*('Projects Overview'!R$2:R$5021))} -> 0 | J22: {=SUMPRODUCT(('Projects Overview'!$B$2:$B$5021="Female Stab")*('Projects Overview'!$G$2:$G$5021="Risk Release")*('Projects Overview'!S$2:S$5021))} -> 0 | K22: {=SUMPRODUCT(('Projects Overview'!$B$2:$B$5021="Female Stab")*('Projects Overview'!$G$2:$G$5021="Risk Release")*('Projects Overview'!T$2:T$5021))} -> 0 | L22: {=SUMPRODUCT(('Projects Overview'!$B$2:$B$5021="Female Stab")*('Projects Overview'!$G$2:$G$5021="Risk Release")*('Projects Overview'!U$2:U$5021))} -> 0 | M22: {=SUMPRODUCT(('Projects Overview'!$B$2:$B$5021="Female Stab")*('Projects Overview'!$G$2:$G$5021="Risk Release")*('Projects Overview'!V$2:V$5021))} -> 0 | N22: {=SUMPRODUCT(('Projects Overview'!$B$2:$B$5021="Female Stab")*('Projects Overview'!$G$2:$G$5021="Risk Release")*('Projects Overview'!W$2:W$5021))} -> 0 | O22: {=SUMPRODUCT(('Projects Overview'!$B$2:$B$5021="Female Stab")*('Projects Overview'!$G$2:$G$5021="Risk Release")*('Projects Overview'!X$2:X$5021))} -> 0 | P22: {=SUMPRODUCT(('Projects Overview'!$B$2:$B$5021="Female Stab")*('Projects Overview'!$G$2:$G$5021="Risk Release")*('Projects Overview'!Y$2:Y$5021))} -> 0 | ... AM22: {=SUMPRODUCT(('Projects Overview'!$B$2:$B$5021="Female Stab")*('Projects Overview'!$G$2:$G$5021="Risk Release")*('Projects Overview'!AV$2:AV$5021))} -> 0 | BE22: Current Workshop Capacity per quarter | BF22: Headcount | BG22: Total Hours
C23: Forecast | D23: 0 | E23: 0 | F23: 0 | G23: 0 | H23: 0 | I23: {=SUMPRODUCT(('Projects Overview'!$B$2:$B$5021="Female Stab")*('Projects Overview'!$G$2:$G$5021="Forecast")*('Projects Overview'!R$2:R$5021))} -> 0 | J23: {=SUMPRODUCT(('Projects Overview'!$B$2:$B$5021="Female Stab")*('Projects Overview'!$G$2:$G$5021="Forecast")*('Projects Overview'!S$2:S$5021))} -> 0 | K23: {=SUMPRODUCT(('Projects Overview'!$B$2:$B$5021="Female Stab")*('Projects Overview'!$G$2:$G$5021="Forecast")*('Projects Overview'!T$2:T$5021))} -> 0 | L23: {=SUMPRODUCT(('Projects Overview'!$B$2:$B$5021="Female Stab")*('Projects Overview'!$G$2:$G$5021="Forecast")*('Projects Overview'!U$2:U$5021))} -> 0 | M23: {=SUMPRODUCT(('Projects Overview'!$B$2:$B$5021="Female Stab")*('Projects Overview'!$G$2:$G$5021="Forecast")*('Projects Overview'!V$2:V$5021))} -> 0 | N23: {=SUMPRODUCT(('Projects Overview'!$B$2:$B$5021="Female Stab")*('Projects Overview'!$G$2:$G$5021="Forecast")*('Projects Overview'!W$2:W$5021))} -> 0 | O23: {=SUMPRODUCT(('Projects Overview'!$B$2:$B$5021="Female Stab")*('Projects Overview'!$G$2:$G$5021="Forecast")*('Projects Overview'!X$2:X$5021))} -> 0 | P23: {=SUMPRODUCT(('Projects Overview'!$B$2:$B$5021="Female Stab")*('Projects Overview'!$G$2:$G$5021="Forecast")*('Projects Overview'!Y$2:Y$5021))} -> 0 | ... AM23: {=SUMPRODUCT(('Projects Overview'!$B$2:$B$5021="Female Stab")*('Projects Overview'!$G$2:$G$5021="Forecast")*('Projects Overview'!AV$2:AV$5021))} -> 0 | BE23: HMH Operational Employees | BF23: =AU59 -> 55 | BG23: =AU56 -> 19630.6
B24: Test Stump | C24: Firm | D24: 0 | E24: 0 | F24: 0 | G24: 0 | H24: 0 | I24: {=SUMPRODUCT(('Projects Overview'!$B$2:$B$5021="Test Stump")*('Projects Overview'!$G$2:$G$5021="Firm")*('Projects Overview'!R$2:R$5021))} -> 0 | J24: {=SUMPRODUCT(('Projects Overview'!$B$2:$B$5021="Test Stump")*('Projects Overview'!$G$2:$G$5021="Firm")*('Projects Overview'!S$2:S$5021))} -> 0 | K24: {=SUMPRODUCT(('Projects Overview'!$B$2:$B$5021="Test Stump")*('Projects Overview'!$G$2:$G$5021="Firm")*('Projects Overview'!T$2:T$5021))} -> 0 | L24: {=SUMPRODUCT(('Projects Overview'!$B$2:$B$5021="Test Stump")*('Projects Overview'!$G$2:$G$5021="Firm")*('Projects Overview'!U$2:U$5021))} -> 0 | M24: {=SUMPRODUCT(('Projects Overview'!$B$2:$B$5021="Test Stump")*('Projects Overview'!$G$2:$G$5021="Firm")*('Projects Overview'!V$2:V$5021))} -> 0 | N24: {=SUMPRODUCT(('Projects Overview'!$B$2:$B$5021="Test Stump")*('Projects Overview'!$G$2:$G$5021="Firm")*('Projects Overview'!W$2:W$5021))} -> 0 | O24: {=SUMPRODUCT(('Projects Overview'!$B$2:$B$5021="Test Stump")*('Projects Overview'!$G$2:$G$5021="Firm")*('Projects Overview'!X$2:X$5021))} -> 0 | P24: {=SUMPRODUCT(('Projects Overview'!$B$2:$B$5021="Test Stump")*('Projects Overview'!$G$2:$G$5021="Firm")*('Projects Overview'!Y$2:Y$5021))} -> 0 | ... AM24: {=SUMPRODUCT(('Projects Overview'!$B$2:$B$5021="Test Stump")*('Projects Overview'!$G$2:$G$5021="Firm")*('Projects Overview'!AV$2:AV$5021))} -> 0 | BE24: Sub Contractors | BF24: 44 | BG24: =AU57-AU56 -> 17505.693
C25: Risk Release | D25: 0 | E25: 0 | F25: 0 | G25: 0 | H25: 0 | I25: {=SUMPRODUCT(('Projects Overview'!$B$2:$B$5021="Test Stump")*('Projects Overview'!$G$2:$G$5021="Risk Release")*('Projects Overview'!R$2:R$5021))} -> 0 | J25: {=SUMPRODUCT(('Projects Overview'!$B$2:$B$5021="Test Stump")*('Projects Overview'!$G$2:$G$5021="Risk Release")*('Projects Overview'!S$2:S$5021))} -> 0 | K25: {=SUMPRODUCT(('Projects Overview'!$B$2:$B$5021="Test Stump")*('Projects Overview'!$G$2:$G$5021="Risk Release")*('Projects Overview'!T$2:T$5021))} -> 0 | L25: {=SUMPRODUCT(('Projects Overview'!$B$2:$B$5021="Test Stump")*('Projects Overview'!$G$2:$G$5021="Risk Release")*('Projects Overview'!U$2:U$5021))} -> 0 | M25: {=SUMPRODUCT(('Projects Overview'!$B$2:$B$5021="Test Stump")*('Projects Overview'!$G$2:$G$5021="Risk Release")*('Projects Overview'!V$2:V$5021))} -> 0 | N25: {=SUMPRODUCT(('Projects Overview'!$B$2:$B$5021="Test Stump")*('Projects Overview'!$G$2:$G$5021="Risk Release")*('Projects Overview'!W$2:W$5021))} -> 0 | O25: {=SUMPRODUCT(('Projects Overview'!$B$2:$B$5021="Test Stump")*('Projects Overview'!$G$2:$G$5021="Risk Release")*('Projects Overview'!X$2:X$5021))} -> 0 | P25: {=SUMPRODUCT(('Projects Overview'!$B$2:$B$5021="Test Stump")*('Projects Overview'!$G$2:$G$5021="Risk Release")*('Projects Overview'!Y$2:Y$5021))} -> 0 | ... AM25: {=SUMPRODUCT(('Projects Overview'!$B$2:$B$5021="Test Stump")*('Projects Overview'!$G$2:$G$5021="Risk Release")*('Projects Overview'!AV$2:AV$5021))} -> 0 | BE25: Total Employees | BF25: =SUM(BF23:BF24) -> 99 | BG25: =SUM(BG23:BG24) -> 37136.293
C26: Forecast | D26: 0 | E26: 0 | F26: 0 | G26: 0 | H26: 0 | I26: {=SUMPRODUCT(('Projects Overview'!$B$2:$B$5021="Test Stump")*('Projects Overview'!$G$2:$G$5021="Forecast")*('Projects Overview'!R$2:R$5021))} -> 0 | J26: {=SUMPRODUCT(('Projects Overview'!$B$2:$B$5021="Test Stump")*('Projects Overview'!$G$2:$G$5021="Forecast")*('Projects Overview'!S$2:S$5021))} -> 0 | K26: {=SUMPRODUCT(('Projects Overview'!$B$2:$B$5021="Test Stump")*('Projects Overview'!$G$2:$G$5021="Forecast")*('Projects Overview'!T$2:T$5021))} -> 0 | L26: {=SUMPRODUCT(('Projects Overview'!$B$2:$B$5021="Test Stump")*('Projects Overview'!$G$2:$G$5021="Forecast")*('Projects Overview'!U$2:U$5021))} -> 0 | M26: {=SUMPRODUCT(('Projects Overview'!$B$2:$B$5021="Test Stump")*('Projects Overview'!$G$2:$G$5021="Forecast")*('Projects Overview'!V$2:V$5021))} -> 0 | N26: {=SUMPRODUCT(('Projects Overview'!$B$2:$B$5021="Test Stump")*('Projects Overview'!$G$2:$G$5021="Forecast")*('Projects Overview'!W$2:W$5021))} -> 0 | O26: {=SUMPRODUCT(('Projects Overview'!$B$2:$B$5021="Test Stump")*('Projects Overview'!$G$2:$G$5021="Forecast")*('Projects Overview'!X$2:X$5021))} -> 0 | P26: {=SUMPRODUCT(('Projects Overview'!$B$2:$B$5021="Test Stump")*('Projects Overview'!$G$2:$G$5021="Forecast")*('Projects Overview'!Y$2:Y$5021))} -> 0 | ... AM26: {=SUMPRODUCT(('Projects Overview'!$B$2:$B$5021="Test Stump")*('Projects Overview'!$G$2:$G$5021="Forecast")*('Projects Overview'!AV$2:AV$5021))} -> 0
B27: Diverter | C27: Firm | D27: 308 | E27: 0 | F27: 0 | G27: 0 | H27: 0 | I27: {=SUMPRODUCT(('Projects Overview'!$B$2:$B$5021="Diverter")*('Projects Overview'!$G$2:$G$5021="Firm")*('Projects Overview'!R$2:R$5021))} -> 0 | J27: {=SUMPRODUCT(('Projects Overview'!$B$2:$B$5021="Diverter")*('Projects Overview'!$G$2:$G$5021="Firm")*('Projects Overview'!S$2:S$5021))} -> 0 | K27: {=SUMPRODUCT(('Projects Overview'!$B$2:$B$5021="Diverter")*('Projects Overview'!$G$2:$G$5021="Firm")*('Projects Overview'!T$2:T$5021))} -> 0 | L27: {=SUMPRODUCT(('Projects Overview'!$B$2:$B$5021="Diverter")*('Projects Overview'!$G$2:$G$5021="Firm")*('Projects Overview'!U$2:U$5021))} -> 0 | M27: {=SUMPRODUCT(('Projects Overview'!$B$2:$B$5021="Diverter")*('Projects Overview'!$G$2:$G$5021="Firm")*('Projects Overview'!V$2:V$5021))} -> 0 | N27: {=SUMPRODUCT(('Projects Overview'!$B$2:$B$5021="Diverter")*('Projects Overview'!$G$2:$G$5021="Firm")*('Projects Overview'!W$2:W$5021))} -> 0 | O27: {=SUMPRODUCT(('Projects Overview'!$B$2:$B$5021="Diverter")*('Projects Overview'!$G$2:$G$5021="Firm")*('Projects Overview'!X$2:X$5021))} -> 0 | P27: {=SUMPRODUCT(('Projects Overview'!$B$2:$B$5021="Diverter")*('Projects Overview'!$G$2:$G$5021="Firm")*('Projects Overview'!Y$2:Y$5021))} -> 0 | ... AM27: {=SUMPRODUCT(('Projects Overview'!$B$2:$B$5021="Diverter")*('Projects Overview'!$G$2:$G$5021="Firm")*('Projects Overview'!AV$2:AV$5021))} -> 0
C28: Risk Release | D28: 0 | E28: 0 | F28: 0 | G28: 0 | H28: 0 | I28: {=SUMPRODUCT(('Projects Overview'!$B$2:$B$5021="Diverter")*('Projects Overview'!$G$2:$G$5021="Risk Release")*('Projects Overview'!R$2:R$5021))} -> 0 | J28: {=SUMPRODUCT(('Projects Overview'!$B$2:$B$5021="Diverter")*('Projects Overview'!$G$2:$G$5021="Risk Release")*('Projects Overview'!S$2:S$5021))} -> 0 | K28: {=SUMPRODUCT(('Projects Overview'!$B$2:$B$5021="Diverter")*('Projects Overview'!$G$2:$G$5021="Risk Release")*('Projects Overview'!T$2:T$5021))} -> 0 | L28: {=SUMPRODUCT(('Projects Overview'!$B$2:$B$5021="Diverter")*('Projects Overview'!$G$2:$G$5021="Risk Release")*('Projects Overview'!U$2:U$5021))} -> 0 | M28: {=SUMPRODUCT(('Projects Overview'!$B$2:$B$5021="Diverter")*('Projects Overview'!$G$2:$G$5021="Risk Release")*('Projects Overview'!V$2:V$5021))} -> 0 | N28: {=SUMPRODUCT(('Projects Overview'!$B$2:$B$5021="Diverter")*('Projects Overview'!$G$2:$G$5021="Risk Release")*('Projects Overview'!W$2:W$5021))} -> 0 | O28: {=SUMPRODUCT(('Projects Overview'!$B$2:$B$5021="Diverter")*('Projects Overview'!$G$2:$G$5021="Risk Release")*('Projects Overview'!X$2:X$5021))} -> 0 | P28: {=SUMPRODUCT(('Projects Overview'!$B$2:$B$5021="Diverter")*('Projects Overview'!$G$2:$G$5021="Risk Release")*('Projects Overview'!Y$2:Y$5021))} -> 0 | ... AM28: {=SUMPRODUCT(('Projects Overview'!$B$2:$B$5021="Diverter")*('Projects Overview'!$G$2:$G$5021="Risk Release")*('Projects Overview'!AV$2:AV$5021))} -> 0
C29: Forecast | D29: 0 | E29: 0 | F29: 0 | G29: 0 | H29: 0 | I29: {=SUMPRODUCT(('Projects Overview'!$B$2:$B$5021="Diverter")*('Projects Overview'!$G$2:$G$5021="Forecast")*('Projects Overview'!R$2:R$5021))} -> 0 | J29: {=SUMPRODUCT(('Projects Overview'!$B$2:$B$5021="Diverter")*('Projects Overview'!$G$2:$G$5021="Forecast")*('Projects Overview'!S$2:S$5021))} -> 0 | K29: {=SUMPRODUCT(('Projects Overview'!$B$2:$B$5021="Diverter")*('Projects Overview'!$G$2:$G$5021="Forecast")*('Projects Overview'!T$2:T$5021))} -> 0 | L29: {=SUMPRODUCT(('Projects Overview'!$B$2:$B$5021="Diverter")*('Projects Overview'!$G$2:$G$5021="Forecast")*('Projects Overview'!U$2:U$5021))} -> 0 | M29: {=SUMPRODUCT(('Projects Overview'!$B$2:$B$5021="Diverter")*('Projects Overview'!$G$2:$G$5021="Forecast")*('Projects Overview'!V$2:V$5021))} -> 0 | N29: {=SUMPRODUCT(('Projects Overview'!$B$2:$B$5021="Diverter")*('Projects Overview'!$G$2:$G$5021="Forecast")*('Projects Overview'!W$2:W$5021))} -> 0 | O29: {=SUMPRODUCT(('Projects Overview'!$B$2:$B$5021="Diverter")*('Projects Overview'!$G$2:$G$5021="Forecast")*('Projects Overview'!X$2:X$5021))} -> 0 | P29: {=SUMPRODUCT(('Projects Overview'!$B$2:$B$5021="Diverter")*('Projects Overview'!$G$2:$G$5021="Forecast")*('Projects Overview'!Y$2:Y$5021))} -> 0 | ... AM29: {=SUMPRODUCT(('Projects Overview'!$B$2:$B$5021="Diverter")*('Projects Overview'!$G$2:$G$5021="Forecast")*('Projects Overview'!AV$2:AV$5021))} -> 0
B30: Ram Block | C30: Firm | D30: 308.8 | E30: 608.8 | F30: 994.8 | G30: 994.8 | H30: 837.8 | I30: {=SUMPRODUCT(('Projects Overview'!$B$2:$B$5021="Ram Block")*('Projects Overview'!$G$2:$G$5021="Firm")*('Projects Overview'!R$2:R$5021))} -> 722 | J30: {=SUMPRODUCT(('Projects Overview'!$B$2:$B$5021="Ram Block")*('Projects Overview'!$G$2:$G$5021="Firm")*('Projects Overview'!S$2:S$5021))} -> 800 | K30: {=SUMPRODUCT(('Projects Overview'!$B$2:$B$5021="Ram Block")*('Projects Overview'!$G$2:$G$5021="Firm")*('Projects Overview'!T$2:T$5021))} -> 534 | L30: {=SUMPRODUCT(('Projects Overview'!$B$2:$B$5021="Ram Block")*('Projects Overview'!$G$2:$G$5021="Firm")*('Projects Overview'!U$2:U$5021))} -> 356 | M30: {=SUMPRODUCT(('Projects Overview'!$B$2:$B$5021="Ram Block")*('Projects Overview'!$G$2:$G$5021="Firm")*('Projects Overview'!V$2:V$5021))} -> 470 | N30: {=SUMPRODUCT(('Projects Overview'!$B$2:$B$5021="Ram Block")*('Projects Overview'!$G$2:$G$5021="Firm")*('Projects Overview'!W$2:W$5021))} -> 260 | O30: {=SUMPRODUCT(('Projects Overview'!$B$2:$B$5021="Ram Block")*('Projects Overview'!$G$2:$G$5021="Firm")*('Projects Overview'!X$2:X$5021))} -> 0 | P30: {=SUMPRODUCT(('Projects Overview'!$B$2:$B$5021="Ram Block")*('Projects Overview'!$G$2:$G$5021="Firm")*('Projects Overview'!Y$2:Y$5021))} -> 0 | ... AM30: {=SUMPRODUCT(('Projects Overview'!$B$2:$B$5021="Ram Block")*('Projects Overview'!$G$2:$G$5021="Firm")*('Projects Overview'!AV$2:AV$5021))} -> 0
C31: Risk Release | D31: 0 | E31: 0 | F31: 0 | G31: 0 | H31: 0 | I31: {=SUMPRODUCT(('Projects Overview'!$B$2:$B$5021="Ram Block")*('Projects Overview'!$G$2:$G$5021="Risk Release")*('Projects Overview'!R$2:R$5021))} -> 0 | J31: {=SUMPRODUCT(('Projects Overview'!$B$2:$B$5021="Ram Block")*('Projects Overview'!$G$2:$G$5021="Risk Release")*('Projects Overview'!S$2:S$5021))} -> 0 | K31: {=SUMPRODUCT(('Projects Overview'!$B$2:$B$5021="Ram Block")*('Projects Overview'!$G$2:$G$5021="Risk Release")*('Projects Overview'!T$2:T$5021))} -> 0 | L31: {=SUMPRODUCT(('Projects Overview'!$B$2:$B$5021="Ram Block")*('Projects Overview'!$G$2:$G$5021="Risk Release")*('Projects Overview'!U$2:U$5021))} -> 0 | M31: {=SUMPRODUCT(('Projects Overview'!$B$2:$B$5021="Ram Block")*('Projects Overview'!$G$2:$G$5021="Risk Release")*('Projects Overview'!V$2:V$5021))} -> 0 | N31: {=SUMPRODUCT(('Projects Overview'!$B$2:$B$5021="Ram Block")*('Projects Overview'!$G$2:$G$5021="Risk Release")*('Projects Overview'!W$2:W$5021))} -> 0 | O31: {=SUMPRODUCT(('Projects Overview'!$B$2:$B$5021="Ram Block")*('Projects Overview'!$G$2:$G$5021="Risk Release")*('Projects Overview'!X$2:X$5021))} -> 0 | P31: {=SUMPRODUCT(('Projects Overview'!$B$2:$B$5021="Ram Block")*('Projects Overview'!$G$2:$G$5021="Risk Release")*('Projects Overview'!Y$2:Y$5021))} -> 0 | ... AM31: {=SUMPRODUCT(('Projects Overview'!$B$2:$B$5021="Ram Block")*('Projects Overview'!$G$2:$G$5021="Risk Release")*('Projects Overview'!AV$2:AV$5021))} -> 0
C32: Forecast | D32: 0 | E32: 0 | F32: 0 | G32: 0 | H32: 0 | I32: {=SUMPRODUCT(('Projects Overview'!$B$2:$B$5021="Ram Block")*('Projects Overview'!$G$2:$G$5021="Forecast")*('Projects Overview'!R$2:R$5021))} -> 0 | J32: {=SUMPRODUCT(('Projects Overview'!$B$2:$B$5021="Ram Block")*('Projects Overview'!$G$2:$G$5021="Forecast")*('Projects Overview'!S$2:S$5021))} -> 0 | K32: {=SUMPRODUCT(('Projects Overview'!$B$2:$B$5021="Ram Block")*('Projects Overview'!$G$2:$G$5021="Forecast")*('Projects Overview'!T$2:T$5021))} -> 0 | L32: {=SUMPRODUCT(('Projects Overview'!$B$2:$B$5021="Ram Block")*('Projects Overview'!$G$2:$G$5021="Forecast")*('Projects Overview'!U$2:U$5021))} -> 0 | M32: {=SUMPRODUCT(('Projects Overview'!$B$2:$B$5021="Ram Block")*('Projects Overview'!$G$2:$G$5021="Forecast")*('Projects Overview'!V$2:V$5021))} -> 0 | N32: {=SUMPRODUCT(('Projects Overview'!$B$2:$B$5021="Ram Block")*('Projects Overview'!$G$2:$G$5021="Forecast")*('Projects Overview'!W$2:W$5021))} -> 0 | O32: {=SUMPRODUCT(('Projects Overview'!$B$2:$B$5021="Ram Block")*('Projects Overview'!$G$2:$G$5021="Forecast")*('Projects Overview'!X$2:X$5021))} -> 0 | P32: {=SUMPRODUCT(('Projects Overview'!$B$2:$B$5021="Ram Block")*('Projects Overview'!$G$2:$G$5021="Forecast")*('Projects Overview'!Y$2:Y$5021))} -> 0 | ... AM32: {=SUMPRODUCT(('Projects Overview'!$B$2:$B$5021="Ram Block")*('Projects Overview'!$G$2:$G$5021="Forecast")*('Projects Overview'!AV$2:AV$5021))} -> 0
B33: Ram BOP | C33: Firm | D33: 0 | E33: 0 | F33: 0 | G33: 0 | H33: 0 | I33: {=SUMPRODUCT(('Projects Overview'!$B$2:$B$5021="Ram BOP")*('Projects Overview'!$G$2:$G$5021="Firm")*('Projects Overview'!R$2:R$5021))} -> 0 | J33: {=SUMPRODUCT(('Projects Overview'!$B$2:$B$5021="Ram BOP")*('Projects Overview'!$G$2:$G$5021="Firm")*('Projects Overview'!S$2:S$5021))} -> 0 | K33: {=SUMPRODUCT(('Projects Overview'!$B$2:$B$5021="Ram BOP")*('Projects Overview'!$G$2:$G$5021="Firm")*('Projects Overview'!T$2:T$5021))} -> 0 | L33: {=SUMPRODUCT(('Projects Overview'!$B$2:$B$5021="Ram BOP")*('Projects Overview'!$G$2:$G$5021="Firm")*('Projects Overview'!U$2:U$5021))} -> 0 | M33: {=SUMPRODUCT(('Projects Overview'!$B$2:$B$5021="Ram BOP")*('Projects Overview'!$G$2:$G$5021="Firm")*('Projects Overview'!V$2:V$5021))} -> 0 | N33: {=SUMPRODUCT(('Projects Overview'!$B$2:$B$5021="Ram BOP")*('Projects Overview'!$G$2:$G$5021="Firm")*('Projects Overview'!W$2:W$5021))} -> 0 | O33: {=SUMPRODUCT(('Projects Overview'!$B$2:$B$5021="Ram BOP")*('Projects Overview'!$G$2:$G$5021="Firm")*('Projects Overview'!X$2:X$5021))} -> 0 | P33: {=SUMPRODUCT(('Projects Overview'!$B$2:$B$5021="Ram BOP")*('Projects Overview'!$G$2:$G$5021="Firm")*('Projects Overview'!Y$2:Y$5021))} -> 0 | ... AM33: {=SUMPRODUCT(('Projects Overview'!$B$2:$B$5021="Ram BOP")*('Projects Overview'!$G$2:$G$5021="Firm")*('Projects Overview'!AV$2:AV$5021))} -> 0
